Workbook
Name Days: #REF!
Name Days: 'FRI-Dataset'!$D$2
Name Days: #REF!
Name ProjectYears: #REF!
Name ProjectYears: #REF!
Name ProjectYears: #REF!
Name SectorCodes: #REF!
Name SectorCodes: #REF!
Name SectorCodes: #REF!
Name SectorCodes: #REF!
Name SectorNames: #REF!
Name SectorNames: #REF!
Name SectorNames: #REF!
Name SectorNames: #REF!

Sheet Cover
B2: Toward an Integrated Assessment of Financial Resilience and Governance in Tunisian Non-Listed SMEs
A7: WORKBOOK NAVIGATION
A9: DATA & METHODOLOGY FOUNDATIONS | K9: PORTFOLIO MAPPING
A10: FRI-Dataset | K10: Cluster Firms
A11: Formula Dictionary | K11: Cluster Summary
A12: Sector Grouping | K12: Silhouette
A13: PCA Diagnostics | K13: Benchmarking
A14: STATISTICAL EVIDENCE | K14: DECISION SUPPORT APPLICATION
A15: FRI Results | K15: Decision Table
A16: FRI by Firm | K16: Sensitivity Analysis
A17: Descriptives | K17: Case Study
A18: Spearman | K18: CORRELATION ANALYSIS & VISUALS
A19: Bootstrap | K19: Pillar Correlations
A20: Wilcoxon | K20: FRI Visualizations
A21: Governance Score | K21: Decision Framework – Charts
A22: G_score vs FRI
A23: Synthesis

Sheet FRI-Dataset
B1: IRF Pillars Calculator
B2: Days | D2: 365
B4: Identifiers | E4: Raw Inputs / Controls | U4: Derived Input | V4: Liquidity | Y4: Cash Generation | AB4: Capital Structure | AE4: Debt Sustainability
B5: Firm_ID | C5: Sector | D5: Year | E5: Revenue | F5: Current Assets | G5: Current Liabilities | H5: Cash & Cash Eq. | I5: Accounts Receivables | J5: Total Assets | K5: ST Debt | L5: LT Debt | M5: Total Equity | N5: Retained Earnings | O5: EBIT | P5: Interest Expense | Q5: Net Income | R5: Depreciation & Amort. | S5: Cash flow from oprations | T5: EBITDA | U5: Total Financial Debt | V5: Current Ratio | W5: Working Capital / Total Assets | X5: Receivables Days | Y5: EBITDA / Total Assets | Z5: CFO / Revenue | AA5: Asset Turnover | AB5: Equity Ratio | AC5: Financial Debt / TA | AD5: Retained Earnings / TA | AE5: Interest Coverage Ratio (ICR) | AF5: CFO / Interest Coverage | AG5: CFO / Financial Debt
B6: F01 | C6: =_xlfn.XLOOKUP(B6,Sector_Grouping!$A$4:$A$18,Sector_Grouping!$C$4:$C$18,"") -> Services and Commerce | D6: 2020 | E6: 20211488 | F6: 11228835 | G6: 13091101 | H6: 89079.112 | I6: 2743202.8 | J6: 24794637 | K6: 1763525.8 | L6: 6692537.4 | M6: 4458554.4 | N6: 3812210.1 | O6: -409817.08 | P6: 429897.77 | Q6: -537954.7 | R6: 1525847.5 | S6: -1205642.8 | T6: =O6+R6 -> 1116030.4 | U6: =K6+L6 -> 8456063.2 | V6: =IF(G6=0,"",F6/G6) -> 0.85774565 | W6: =IF(J6=0,"",(F6-G6)/J6) -> -0.075107612 | X6: =IF(E6=0,"",(I6/E6)*Days) -> 49.539599 | Y6: =IF(J6=0,"",T6/J6) -> 0.04501096 | Z6: =IF(E6=0,"",S6/E6) -> -0.059651359 | AA6: =IF(J6=0,"",E6/J6) -> 0.81515564 | AB6: =IF(U6=0,"",M6/J6) -> 0.1798193 | AC6: =IF(J6=0,"",U6/J6) -> 0.34104404 | AD6: =IF(J6=0,"",N6/J6) -> 0.1537514 | AE6: =IF(P6=0,"",O6/P6) -> -0.95328961 | AF6: =IF(P6=0,"N/A",S6/P6) -> -2.8044871 | AG6: =IF(U6=0,"",(S6/U6)) -> -0.14257731
B7: F01 | C7: =_xlfn.XLOOKUP(B7,Sector_Grouping!$A$4:$A$18,Sector_Grouping!$C$4:$C$18,"") -> Services and Commerce | D7: 2021 | E7: 23721959 | F7: 13720759 | G7: 14137495 | H7: 380068.85 | I7: 3501099.3 | J7: 25643521 | K7: 1533193.7 | L7: 7407135.8 | M7: 3546445.4 | N7: 3274255.4 | O7: -194852.1 | P7: 841464.76 | Q7: -912108.97 | R7: 1616805.8 | S7: -219511.6 | T7: =O7+R7 -> 1421953.7 | U7: =K7+L7 -> 8940329.5 | V7: =IF(G7=0,"",F7/G7) -> 0.97052266 | W7: =IF(J7=0,"",(F7-G7)/J7) -> -0.01625111 | X7: =IF(E7=0,"",(I7/E7)*Days) -> 53.869972 | Y7: =IF(J7=0,"",T7/J7) -> 0.0554508 | Z7: =IF(E7=0,"",S7/E7) -> -0.009253519 | AA7: =IF(J7=0,"",E7/J7) -> 0.92506636 | AB7: =IF(U7=0,"",M7/J7) -> 0.13829791 | AC7: =IF(J7=0,"",U7/J7) -> 0.34863892 | AD7: =IF(J7=0,"",N7/J7) -> 0.12768353 | AE7: =IF(P7=0,"",O7/P7) -> -0.23156299 | AF7: =IF(P7=0,"N/A",S7/P7) -> -0.26086844 | AG7: =IF(U7=0,"",(S7/U7)) -> -0.024552965
B8: F01 | C8: =_xlfn.XLOOKUP(B8,Sector_Grouping!$A$4:$A$18,Sector_Grouping!$C$4:$C$18,"") -> Services and Commerce | D8: 2022 | E8: 35432832 | F8: 15461713 | G8: 15738947 | H8: 500009.47 | I8: 4157035.2 | J8: 26589496 | K8: 2480676.6 | L8: 5719600.9 | M8: 3978503.1 | N8: 2362146.4 | O8: 1055584.1 | P8: 857643.64 | Q8: 432057.73 | R8: =2207265.985 -> 2207266 | S8: 1672279.6 | T8: =O8+R8 -> 3262850.1 | U8: =K8+L8 -> 8200277.5 | V8: =IF(G8=0,"",F8/G8) -> 0.98238548 | W8: =IF(J8=0,"",(F8-G8)/J8) -> -0.010426446 | X8: =IF(E8=0,"",(I8/E8)*Days) -> 42.82237 | Y8: =IF(J8=0,"",T8/J8) -> 0.12271199 | Z8: =IF(E8=0,"",S8/E8) -> 0.047195765 | AA8: =IF(J8=0,"",E8/J8) -> 1.3325876 | AB8: =IF(U8=0,"",M8/J8) -> 0.14962687 | AC8: =IF(J8=0,"",U8/J8) -> 0.30840289 | AD8: =IF(J8=0,"",N8/J8) -> 0.088837576 | AE8: =IF(P8=0,"",O8/P8) -> 1.2307957 | AF8: =IF(P8=0,"N/A",S8/P8) -> 1.9498537 | AG8: =IF(U8=0,"",(S8/U8)) -> 0.20392964
B9: F01 | C9: =_xlfn.XLOOKUP(B9,Sector_Grouping!$A$4:$A$18,Sector_Grouping!$C$4:$C$18,"") -> Services and Commerce | D9: 2023 | E9: 42035572 | F9: 19340584 | G9: 18951398 | H9: 478135.48 | I9: 5895796.7 | J9: 37225084 | K9: 2754138 | L9: 5099463.1 | M9: 11311746 | N9: 3560058.6 | O9: 1985418.1 | P9: 814494.57 | Q9: 1577369.8 | R9: 1403777.4 | S9: 3603121.9 | T9: =O9+R9 -> 3389195.5 | U9: =K9+L9 -> 7853601.1 | V9: =IF(G9=0,"",F9/G9) -> 1.020536 | W9: =IF(J9=0,"",(F9-G9)/J9) -> 0.010454941 | X9: =IF(E9=0,"",(I9/E9)*Days) -> 51.193922 | Y9: =IF(J9=0,"",T9/J9) -> 0.091046016 | Z9: =IF(E9=0,"",S9/E9) -> 0.08571602 | AA9: =IF(J9=0,"",E9/J9) -> 1.1292271 | AB9: =IF(U9=0,"",M9/J9) -> 0.3038743 | AC9: =IF(J9=0,"",U9/J9) -> 0.21097605 | AD9: =IF(J9=0,"",N9/J9) -> 0.095636015 | AE9: =IF(P9=0,"",O9/P9) -> 2.4376075 | AF9: =IF(P9=0,"N/A",S9/P9) -> 4.4237519 | AG9: =IF(U9=0,"",(S9/U9)) -> 0.45878596
B10: F01 | C10: =_xlfn.XLOOKUP(B10,Sector_Grouping!$A$4:$A$18,Sector_Grouping!$C$4:$C$18,"") -> Services and Commerce | D10: 2024 | E10: 44599721 | F10: 18286877 | G10: 18971261 | H10: 150043.35 | I10: 7189025.2 | J10: 36139692 | K10: 2313320.4 | L10: 3586120.5 | M10: 11219835 | N10: 3637428.4 | O10: 2547485.7 | P10: 779039.83 | Q10: 1408088.7 | R10: 1353618.6 | S10: 5094359.3 | T10: =O10+R10 -> 3901104.4 | U10: =K10+L10 -> 5899440.9 | V10: =IF(G10=0,"",F10/G10) -> 0.96392524 | W10: =IF(J10=0,"",(F10-G10)/J10) -> -0.018937174 | X10: =IF(E10=0,"",(I10/E10)*Days) -> 58.834318 | Y10: =IF(J10=0,"",T10/J10) -> 0.10794515 | Z10: =IF(E10=0,"",S10/E10) -> 0.11422402 | AA10: =IF(J10=0,"",E10/J10) -> 1.2340925 | AB10: =IF(U10=0,"",M10/J10) -> 0.3104574 | AC10: =IF(J10=0,"",U10/J10) -> 0.16323993 | AD10: =IF(J10=0,"",N10/J10) -> 0.10064913 | AE10: =IF(P10=0,"",O10/P10) -> 3.2700327 | AF10: =IF(P10=0,"N/A",S10/P10) -> 6.5392796 | AG10: =IF(U10=0,"",(S10/U10)) -> 0.86353255
B11: F02 | C11: =_xlfn.XLOOKUP(B11,Sector_Grouping!$A$4:$A$18,Sector_Grouping!$C$4:$C$18,"") -> Agri-food Industry | D11: 2020 | E11: 1512928 | F11: 1570443 | G11: 2262342 | H11: 3935 | I11: 572727 | J11: 4246985 | K11: 923434 | L11: 1702146 | M11: 282497 | N11: 331269 | O11: -446151 | P11: 136724 | Q11: -548772 | R11: 208539 | S11: -312346 | T11: =O11+R11 -> -237612 | U11: =K11+L11 -> 2625580 | V11: =IF(G11=0,"",F11/G11) -> 0.69416693 | W11: =IF(J11=0,"",(F11-G11)/J11) -> -0.16291534 | X11: =IF(E11=0,"",(I11/E11)*Days) -> 138.17271 | Y11: =IF(J11=0,"",T11/J11) -> -0.055948396 | Z11: =IF(E11=0,"",S11/E11) -> -0.20645133 | AA11: =IF(J11=0,"",E11/J11) -> 0.35623578 | AB11: =IF(U11=0,"",M11/J11) -> 0.06651707 | AC11: =IF(J11=0,"",U11/J11) -> 0.6182221 | AD11: =IF(J11=0,"",N11/J11) -> 0.078000982 | AE11: =IF(P11=0,"",O11/P11) -> -3.2631506 | AF11: =IF(P11=0,"N/A",S11/P11) -> -2.2845002 | AG11: =IF(U11=0,"",(S11/U11)) -> -0.11896267
B12: F02 | C12: =_xlfn.XLOOKUP(B12,Sector_Grouping!$A$4:$A$18,Sector_Grouping!$C$4:$C$18,"") -> Agri-food Industry | D12: 2021 | E12: 2810637 | F12: 1536296 | G12: 2554314 | H12: 10045 | I12: 110607 | J12: 3998376 | K12: 801064 | L12: 1350130 | M12: 93932 | N12: -217503 | O12: -133466 | P12: 236369 | Q12: -384107 | R12: 287785 | S12: 528332 | T12: =O12+R12 -> 154319 | U12: =K12+L12 -> 2151194 | V12: =IF(G12=0,"",F12/G12) -> 0.60145151 | W12: =IF(J12=0,"",(F12-G12)/J12) -> -0.25460787 | X12: =IF(E12=0,"",(I12/E12)*Days) -> 14.363845 | Y12: =IF(J12=0,"",T12/J12) -> 0.03859542 | Z12: =IF(E12=0,"",S12/E12) -> 0.18797589 | AA12: =IF(J12=0,"",E12/J12) -> 0.70294465 | AB12: =IF(U12=0,"",M12/J12) -> 0.023492538 | AC12: =IF(J12=0,"",U12/J12) -> 0.53801693 | AD12: =IF(J12=0,"",N12/J12) -> -0.054397836 | AE12: =IF(P12=0,"",O12/P12) -> -0.56465103 | AF12: =IF(P12=0,"N/A",S12/P12) -> 2.2352 | AG12: =IF(U12=0,"",(S12/U12)) -> 0.24559942
B13: F02 | C13: =_xlfn.XLOOKUP(B13,Sector_Grouping!$A$4:$A$18,Sector_Grouping!$C$4:$C$18,"") -> Agri-food Industry | D13: 2022 | E13: 3249128 | F13: 1820736 | G13: 2166536 | H13: 76656 | I13: 1120515 | J13: 3987351 | K13: 415700 | L13: 1044188 | M13: 776267 | N13: -601609 | O13: -1058060 | P13: 204287 | Q13: -1234257 | R13: 296792 | S13: -495792 | T13: =O13+R13 -> -761268 | U13: =K13+L13 -> 1459888 | V13: =IF(G13=0,"",F13/G13) -> 0.84039037 | W13: =IF(J13=0,"",(F13-G13)/J13) -> -0.086724244 | X13: =IF(E13=0,"",(I13/E13)*Days) -> 125.87623 | Y13: =IF(J13=0,"",T13/J13) -> -0.19092074 | Z13: =IF(E13=0,"",S13/E13) -> -0.15259233 | AA13: =IF(J13=0,"",E13/J13) -> 0.81485879 | AB13: =IF(U13=0,"",M13/J13) -> 0.19468238 | AC13: =IF(J13=0,"",U13/J13) -> 0.36612979 | AD13: =IF(J13=0,"",N13/J13) -> -0.15087937 | AE13: =IF(P13=0,"",O13/P13) -> -5.1792821 | AF13: =IF(P13=0,"N/A",S13/P13) -> -2.4269386 | AG13: =IF(U13=0,"",(S13/U13)) -> -0.33960961
B14: F02 | C14: =_xlfn.XLOOKUP(B14,Sector_Grouping!$A$4:$A$18,Sector_Grouping!$C$4:$C$18,"") -> Agri-food Industry | D14: 2023 | E14: 3690444 | F14: 2045339 | G14: 2234983 | H14: 12711 | I14: 1183251 | J14: 3761604 | K14: 1046429 | L14: 635072 | M14: 891549 | N14: -1835866 | O14: 68244 | P14: 199249 | Q14: 147971 | R14: 307388 | S14: -125302 | T14: =O14+R14 -> 375632 | U14: =K14+L14 -> 1681501 | V14: =IF(G14=0,"",F14/G14) -> 0.91514745 | W14: =IF(J14=0,"",(F14-G14)/J14) -> -0.050415727 | X14: =IF(E14=0,"",(I14/E14)*Days) -> 117.02836 | Y14: =IF(J14=0,"",T14/J14) -> 0.099859528 | Z14: =IF(E14=0,"",S14/E14) -> -0.033953096 | AA14: =IF(J14=0,"",E14/J14) -> 0.98108254 | AB14: =IF(U14=0,"",M14/J14) -> 0.23701299 | AC14: =IF(J14=0,"",U14/J14) -> 0.44701702 | AD14: =IF(J14=0,"",N14/J14) -> -0.48805403 | AE14: =IF(P14=0,"",O14/P14) -> 0.34250611 | AF14: =IF(P14=0,"N/A",S14/P14) -> -0.62887141 | AG14: =IF(U14=0,"",(S14/U14)) -> -0.074517946
B15: F02 | C15: =_xlfn.XLOOKUP(B15,Sector_Grouping!$A$4:$A$18,Sector_Grouping!$C$4:$C$18,"") -> Agri-food Industry | D15: 2024 | E15: 5346533 | F15: 2458925 | G15: 2609560 | H15: 8722 | I15: 1774422 | J15: 4014786 | K15: 896697 | L15: 382582 | M15: 1022645 | N15: -1687895 | O15: 271581 | P15: 168321 | Q15: 164146 | R15: 277248 | S15: 556954 | T15: =O15+R15 -> 548829 | U15: =K15+L15 -> 1279279 | V15: =IF(G15=0,"",F15/G15) -> 0.94227571 | W15: =IF(J15=0,"",(F15-G15)/J15) -> -0.037520057 | X15: =IF(E15=0,"",(I15/E15)*Days) -> 121.1372 | Y15: =IF(J15=0,"",T15/J15) -> 0.13670193 | Z15: =IF(E15=0,"",S15/E15) -> 0.10417106 | AA15: =IF(J15=0,"",E15/J15) -> 1.3317106 | AB15: =IF(U15=0,"",M15/J15) -> 0.25471968 | AC15: =IF(J15=0,"",U15/J15) -> 0.31864189 | AD15: =IF(J15=0,"",N15/J15) -> -0.42041967 | AE15: =IF(P15=0,"",O15/P15) -> 1.6134707 | AF15: =IF(P15=0,"N/A",S15/P15) -> 3.3088801 | AG15: =IF(U15=0,"",(S15/U15)) -> 0.43536555
B16: F03 | C16: =_xlfn.XLOOKUP(B16,Sector_Grouping!$A$4:$A$18,Sector_Grouping!$C$4:$C$18,"") -> Manufacturing Industry | D16: 2019 | E16: 6338113 | F16: 3392695 | G16: 6873941 | H16: 672231 | I16: =519274-130000 -> 389274 | J16: 7633761 | K16: 4737871 | L16: 2505819 | M16: -1745999 | N16: -3385519 | O16: -2114355 | P16: 531863 | Q16: -2630480 | R16: 767019 | S16: -1342190 | T16: =O16+R16 -> -1347336 | U16: =K16+L16 -> 7243690 | V16: =IF(G16=0,"",F16/G16) -> 0.49355894 | W16: =IF(J16=0,"",(F16-G16)/J16) -> -0.45603288 | X16: =IF(E16=0,"",(I16/E16)*Days) -> 22.417557 | Y16: =IF(J16=0,"",T16/J16) -> -0.17649701 | Z16: =IF(E16=0,"",S16/E16) -> -0.21176492 | AA16: =IF(J16=0,"",E16/J16) -> 0.83027396 | AB16: =IF(U16=0,"",M16/J16) -> -0.22872068 | AC16: =IF(J16=0,"",U16/J16) -> 0.94890186 | AD16: =IF(J16=0,"",N16/J16) -> -0.44349293 | AE16: =IF(P16=0,"",O16/P16) -> -3.9753752 | AF16: =IF(P16=0,"N/A",S16/P16) -> -2.5235634 | AG16: =IF(U16=0,"",(S16/U16)) -> -0.18529092
B17: F03 | C17: =_xlfn.XLOOKUP(B17,Sector_Grouping!$A$4:$A$18,Sector_Grouping!$C$4:$C$18,"") -> Manufacturing Industry | D17: 2020 | E17: 7138021 | F17: 2555873 | G17: 6995276 | H17: 268571 | I17: =387139-130000 -> 257139 | J17: 6046469 | K17: 4891333 | L17: 1722487 | M17: -2671295 | N17: -6015999 | O17: -1073237 | P17: 602059 | Q17: -1675296 | R17: 330873 | S17: -253551 | T17: =O17+R17 -> -742364 | U17: =K17+L17 -> 6613820 | V17: =IF(G17=0,"",F17/G17) -> 0.36537129 | W17: =IF(J17=0,"",(F17-G17)/J17) -> -0.73421413 | X17: =IF(E17=0,"",(I17/E17)*Days) -> 13.148705 | Y17: =IF(J17=0,"",T17/J17) -> -0.12277645 | Z17: =IF(E17=0,"",S17/E17) -> -0.03552119 | AA17: =IF(J17=0,"",E17/J17) -> 1.1805272 | AB17: =IF(U17=0,"",M17/J17) -> -0.44179421 | AC17: =IF(J17=0,"",U17/J17) -> 1.0938318 | AD17: =IF(J17=0,"",N17/J17) -> -0.9949607 | AE17: =IF(P17=0,"",O17/P17) -> -1.782611 | AF17: =IF(P17=0,"N/A",S17/P17) -> -0.42113979 | AG17: =IF(U17=0,"",(S17/U17)) -> -0.038336544
B18: F03 | C18: =_xlfn.XLOOKUP(B18,Sector_Grouping!$A$4:$A$18,Sector_Grouping!$C$4:$C$18,"") -> Manufacturing Industry | D18: 2021 | E18: 6749699 | F18: 8270343 | G18: 12348543 | H18: 336198 | I18: 380455 | J18: 10917014 | K18: 7430949 | L18: 1451518 | M18: -2947819 | N18: -9886679 | O18: -2495667 | P18: 779197 | Q18: -3081140 | R18: 1307874 | S18: -4888746 | T18: =O18+R18 -> -1187793 | U18: =K18+L18 -> 8882467 | V18: =IF(G18=0,"",F18/G18) -> 0.66974241 | W18: =IF(J18=0,"",(F18-G18)/J18) -> -0.37356369 | X18: =IF(E18=0,"",(I18/E18)*Days) -> 20.573669 | Y18: =IF(J18=0,"",T18/J18) -> -0.108802 | Z18: =IF(E18=0,"",S18/E18) -> -0.72429096 | AA18: =IF(J18=0,"",E18/J18) -> 0.61827337 | AB18: =IF(U18=0,"",M18/J18) -> -0.27002063 | AC18: =IF(J18=0,"",U18/J18) -> 0.81363521 | AD18: =IF(J18=0,"",N18/J18) -> -0.90562117 | AE18: =IF(P18=0,"",O18/P18) -> -3.2028704 | AF18: =IF(P18=0,"N/A",S18/P18) -> -6.2740822 | AG18: =IF(U18=0,"",(S18/U18)) -> -0.55038156
B19: F03 | C19: =_xlfn.XLOOKUP(B19,Sector_Grouping!$A$4:$A$18,Sector_Grouping!$C$4:$C$18,"") -> Manufacturing Industry | D19: 2022 | E19: 8951813 | F19: 4782386 | G19: 11643300 | H19: 557068 | I19: 339245 | J19: 7147045 | K19: 6497470 | L19: 1819276 | M19: -6470756 | N19: -12967819 | O19: -2412025 | P19: 1090845 | Q19: -3522937 | R19: 882337 | S19: 1508383 | T19: =O19+R19 -> -1529688 | U19: =K19+L19 -> 8316746 | V19: =IF(G19=0,"",F19/G19) -> 0.41074146 | W19: =IF(J19=0,"",(F19-G19)/J19) -> -0.95996513 | X19: =IF(E19=0,"",(I19/E19)*Days) -> 13.832329 | Y19: =IF(J19=0,"",T19/J19) -> -0.21403083 | Z19: =IF(E19=0,"",S19/E19) -> 0.16850028 | AA19: =IF(J19=0,"",E19/J19) -> 1.2525195 | AB19: =IF(U19=0,"",M19/J19) -> -0.90537502 | AC19: =IF(J19=0,"",U19/J19) -> 1.1636622 | AD19: =IF(J19=0,"",N19/J19) -> -1.8144309 | AE19: =IF(P19=0,"",O19/P19) -> -2.2111528 | AF19: =IF(P19=0,"N/A",S19/P19) -> 1.3827657 | AG19: =IF(U19=0,"",(S19/U19)) -> 0.18136697
B20: F03 | C20: =_xlfn.XLOOKUP(B20,Sector_Grouping!$A$4:$A$18,Sector_Grouping!$C$4:$C$18,"") -> Manufacturing Industry | D20: 2023 | E20: 2617189 | F20: 2321534 | G20: 15783128 | H20: =51293-3097 -> 48196 | I20: 169478 | J20: 2923896 | K20: 7492732 | L20: 63167 | M20: -13109808 | N20: -21111966 | O20: -1524323 | P20: 225310 | Q20: -2041388 | R20: 748267 | S20: 3803424 | T20: =O20+R20 -> -776056 | U20: =K20+L20 -> 7555899 | V20: =IF(G20=0,"",F20/G20) -> 0.1470896 | W20: =IF(J20=0,"",(F20-G20)/J20) -> -4.6039921 | X20: =IF(E20=0,"",(I20/E20)*Days) -> 23.635844 | Y20: =IF(J20=0,"",T20/J20) -> -0.26541847 | Z20: =IF(E20=0,"",S20/E20) -> 1.4532477 | AA20: =IF(J20=0,"",E20/J20) -> 0.89510331 | AB20: =IF(U20=0,"",M20/J20) -> -4.4836779 | AC20: =IF(J20=0,"",U20/J20) -> 2.5841887 | AD20: =IF(J20=0,"",N20/J20) -> -7.2204914 | AE20: =IF(P20=0,"",O20/P20) -> -6.7654476 | AF20: =IF(P20=0,"N/A",S20/P20) -> 16.880849 | AG20: =IF(U20=0,"",(S20/U20)) -> 0.50337147
B21: F04 | C21: =_xlfn.XLOOKUP(B21,Sector_Grouping!$A$4:$A$18,Sector_Grouping!$C$4:$C$18,"") -> Manufacturing Industry | D21: 2020 | E21: 3152811.5 | F21: 3271058.5 | G21: 2899882.9 | H21: 577428.6 | I21: 655687.72 | J21: 14800364 | K21: 1276473.4 | L21: 7659374.9 | M21: 4170078.7 | N21: 710668.62 | O21: -1030535.3 | P21: 149599 | Q21: -1200152 | R21: 668689.15 | S21: -25531.923 | T21: =O21+R21 -> -361846.15 | U21: =K21+L21 -> 8935848.3 | V21: =IF(G21=0,"",F21/G21) -> 1.1279968 | W21: =IF(J21=0,"",(F21-G21)/J21) -> 0.02507882 | X21: =IF(E21=0,"",(I21/E21)*Days) -> 75.908761 | Y21: =IF(J21=0,"",T21/J21) -> -0.024448463 | Z21: =IF(E21=0,"",S21/E21) -> -0.0080981443 | AA21: =IF(J21=0,"",E21/J21) -> 0.21302257 | AB21: =IF(U21=0,"",M21/J21) -> 0.28175515 | AC21: =IF(J21=0,"",U21/J21) -> 0.60375869 | AD21: =IF(J21=0,"",N21/J21) -> 0.04801697 | AE21: =IF(P21=0,"",O21/P21) -> -6.888651 | AF21: =IF(P21=0,"N/A",S21/P21) -> -0.17066908 | AG21: =IF(U21=0,"",(S21/U21)) -> -0.0028572467
B22: F04 | C22: =_xlfn.XLOOKUP(B22,Sector_Grouping!$A$4:$A$18,Sector_Grouping!$C$4:$C$18,"") -> Manufacturing Industry | D22: 2021 | E22: 3290433.6 | F22: 3534344.9 | G22: 6115955.3 | H22: 5271.742 | I22: =541992.662-4017.644 -> 537975.02 | J22: 17151029 | K22: 2438451.3 | L22: 8312706.2 | M22: 2575339.9 | N22: -489483.4 | O22: -881397.37 | P22: 751259.48 | Q22: -1596738.8 | R22: 1088804.5 | S22: 712717.05 | T22: =O22+R22 -> 207407.18 | U22: =K22+L22 -> 10751157 | V22: =IF(G22=0,"",F22/G22) -> 0.57788926 | W22: =IF(J22=0,"",(F22-G22)/J22) -> -0.15052219 | X22: =IF(E22=0,"",(I22/E22)*Days) -> 59.676294 | Y22: =IF(J22=0,"",T22/J22) -> 0.012092988 | Z22: =IF(E22=0,"",S22/E22) -> 0.21660278 | AA22: =IF(J22=0,"",E22/J22) -> 0.19185051 | AB22: =IF(U22=0,"",M22/J22) -> 0.15015658 | AC22: =IF(J22=0,"",U22/J22) -> 0.62685205 | AD22: =IF(J22=0,"",N22/J22) -> -0.028539594 | AE22: =IF(P22=0,"",O22/P22) -> -1.1732263 | AF22: =IF(P22=0,"N/A",S22/P22) -> 0.94869625 | AG22: =IF(U22=0,"",(S22/U22)) -> 0.066292123
B23: F04 | C23: =_xlfn.XLOOKUP(B23,Sector_Grouping!$A$4:$A$18,Sector_Grouping!$C$4:$C$18,"") -> Manufacturing Industry | D23: 2022 | E23: 3064464 | F23: 2810941.7 | G23: 6461338.6 | H23: 82989.953 | I23: =412275.654-18099.884 -> 394175.77 | J23: 14360760 | K23: 4251258.3 | L23: 7934317.1 | M23: -271923.32 | N23: -2084222.2 | O23: -2575222.2 | P23: 569554.55 | Q23: -3161052.5 | R23: 568810.33 | S23: -2679736.6 | T23: =O23+R23 -> -2006411.9 | U23: =K23+L23 -> 12185575 | V23: =IF(G23=0,"",F23/G23) -> 0.43504014 | W23: =IF(J23=0,"",(F23-G23)/J23) -> -0.25419247 | X23: =IF(E23=0,"",(I23/E23)*Days) -> 46.949207 | Y23: =IF(J23=0,"",T23/J23) -> -0.13971488 | Z23: =IF(E23=0,"",S23/E23) -> -0.87445523 | AA23: =IF(J23=0,"",E23/J23) -> 0.2133915 | AB23: =IF(U23=0,"",M23/J23) -> -0.018935162 | AC23: =IF(J23=0,"",U23/J23) -> 0.84853278 | AD23: =IF(J23=0,"",N23/J23) -> -0.14513314 | AE23: =IF(P23=0,"",O23/P23) -> -4.5214671 | AF23: =IF(P23=0,"N/A",S23/P23) -> -4.7049691 | AG23: =IF(U23=0,"",(S23/U23)) -> -0.21991055
B24: F04 | C24: =_xlfn.XLOOKUP(B24,Sector_Grouping!$A$4:$A$18,Sector_Grouping!$C$4:$C$18,"") -> Manufacturing Industry | D24: 2023 | E24: 2640653.5 | F24: 3184888 | G24: 6593920.8 | H24: 75541.459 | I24: =537884.072-92966.377 -> 444917.7 | J24: 18376201 | K24: 4282912 | L24: 7648728.5 | M24: 3862401.5 | N24: -2084222.2 | O24: -1750206.4 | P24: 2075642.2 | Q24: -3853239.2 | R24: 1133863 | S24: -2776744 | T24: =O24+R24 -> -616343.43 | U24: =K24+L24 -> 11931640 | V24: =IF(G24=0,"",F24/G24) -> 0.48300368 | W24: =IF(J24=0,"",(F24-G24)/J24) -> -0.18551347 | X24: =IF(E24=0,"",(I24/E24)*Days) -> 61.498019 | Y24: =IF(J24=0,"",T24/J24) -> -0.033540307 | Z24: =IF(E24=0,"",S24/E24) -> -1.0515367 | AA24: =IF(J24=0,"",E24/J24) -> 0.14369964 | AB24: =IF(U24=0,"",M24/J24) -> 0.21018498 | AC24: =IF(J24=0,"",U24/J24) -> 0.64929852 | AD24: =IF(J24=0,"",N24/J24) -> -0.11341964 | AE24: =IF(P24=0,"",O24/P24) -> -0.843212 | AF24: =IF(P24=0,"N/A",S24/P24) -> -1.3377759 | AG24: =IF(U24=0,"",(S24/U24)) -> -0.23272106
B25: F04 | C25: =_xlfn.XLOOKUP(B25,Sector_Grouping!$A$4:$A$18,Sector_Grouping!$C$4:$C$18,"") -> Manufacturing Industry | D25: 2024 | E25: 3275764.1 | F25: 4281350.1 | G25: 7508908.8 | H25: 203575.17 | I25: =102442.149-92966.377 -> 9475.772 | J25: 18444170 | K25: 4356093.3 | L25: 7853812.6 | M25: 2810298 | N25: -2084222.2 | O25: 314427.85 | P25: 1363161.9 | Q25: -1052103.5 | R25: 1082616.9 | S25: -301892.62 | T25: =O25+R25 -> 1397044.8 | U25: =K25+L25 -> 12209906 | V25: =IF(G25=0,"",F25/G25) -> 0.57016942 | W25: =IF(J25=0,"",(F25-G25)/J25) -> -0.17499072 | X25: =IF(E25=0,"",(I25/E25)*Days) -> 1.0558321 | Y25: =IF(J25=0,"",T25/J25) -> 0.075744519 | Z25: =IF(E25=0,"",S25/E25) -> -0.09215945 | AA25: =IF(J25=0,"",E25/J25) -> 0.17760431 | AB25: =IF(U25=0,"",M25/J25) -> 0.15236782 | AC25: =IF(J25=0,"",U25/J25) -> 0.6619927 | AD25: =IF(J25=0,"",N25/J25) -> -0.11300168 | AE25: =IF(P25=0,"",O25/P25) -> 0.23066068 | AF25: =IF(P25=0,"N/A",S25/P25) -> -0.22146498 | AG25: =IF(U25=0,"",(S25/U25)) -> -0.024725221
B26: F05 | C26: =_xlfn.XLOOKUP(B26,Sector_Grouping!$A$4:$A$18,Sector_Grouping!$C$4:$C$18,"") -> Agri-food Industry | D26: 2020 | E26: 2343424.5 | F26: 1978278.2 | G26: 1899610.5 | H26: 33153.605 | I26: 656362.03 | J26: 2733437.3 | K26: 1331326.4 | L26: 732189.67 | M26: 101637.16 | N26: -333483.34 | O26: -92535.984 | P26: 192303.21 | Q26: -249164.39 | R26: 129095.36 | S26: 245751.61 | T26: =O26+R26 -> 36559.374 | U26: =K26+L26 -> 2063516 | V26: =IF(G26=0,"",F26/G26) -> 1.0414126 | W26: =IF(J26=0,"",(F26-G26)/J26) -> 0.028779779 | X26: =IF(E26=0,"",(I26/E26)*Days) -> 102.23164 | Y26: =IF(J26=0,"",T26/J26) -> 0.013374872 | Z26: =IF(E26=0,"",S26/E26) -> 0.10486858 | AA26: =IF(J26=0,"",E26/J26) -> 0.85731781 | AB26: =IF(U26=0,"",M26/J26) -> 0.037182911 | AC26: =IF(J26=0,"",U26/J26) -> 0.75491617 | AD26: =IF(J26=0,"",N26/J26) -> -0.12200146 | AE26: =IF(P26=0,"",O26/P26) -> -0.48119833 | AF26: =IF(P26=0,"N/A",S26/P26) -> 1.2779382 | AG26: =IF(U26=0,"",(S26/U26)) -> 0.11909363
B27: F05 | C27: =_xlfn.XLOOKUP(B27,Sector_Grouping!$A$4:$A$18,Sector_Grouping!$C$4:$C$18,"") -> Agri-food Industry | D27: 2021 | E27: 2396446.6 | F27: 2116713.1 | G27: 1810298.1 | H27: 34569.112 | I27: 869494.84 | J27: 3609961.3 | K27: 340880.89 | L27: 1161020.8 | M27: 638642.42 | N27: -612440.07 | O27: 13563.594 | P27: 223370.66 | Q27: -152298.04 | R27: 185107.67 | S27: -229055.93 | T27: =O27+R27 -> 198671.26 | U27: =K27+L27 -> 1501901.7 | V27: =IF(G27=0,"",F27/G27) -> 1.1692622 | W27: =IF(J27=0,"",(F27-G27)/J27) -> 0.084880409 | X27: =IF(E27=0,"",(I27/E27)*Days) -> 132.43175 | Y27: =IF(J27=0,"",T27/J27) -> 0.055034181 | Z27: =IF(E27=0,"",S27/E27) -> -0.095581488 | AA27: =IF(J27=0,"",E27/J27) -> 0.66384274 | AB27: =IF(U27=0,"",M27/J27) -> 0.17691115 | AC27: =IF(J27=0,"",U27/J27) -> 0.41604371 | AD27: =IF(J27=0,"",N27/J27) -> -0.16965281 | AE27: =IF(P27=0,"",O27/P27) -> 0.060722362 | AF27: =IF(P27=0,"N/A",S27/P27) -> -1.0254522 | AG27: =IF(U27=0,"",(S27/U27)) -> -0.1525106
B28: F05 | C28: =_xlfn.XLOOKUP(B28,Sector_Grouping!$A$4:$A$18,Sector_Grouping!$C$4:$C$18,"") -> Agri-food Industry | D28: 2022 | E28: 2773679.7 | F28: 2455234.1 | G28: 2847537.2 | H28: 53158.713 | I28: 1021655.7 | J28: 3838744 | K28: 909848.94 | L28: 783003.58 | M28: 208203.16 | N28: -764738.11 | O28: -157229.61 | P28: 262580.28 | Q28: -430439.26 | R28: 154766.32 | S28: -54848.489 | T28: =O28+R28 -> -2463.287 | U28: =K28+L28 -> 1692852.5 | V28: =IF(G28=0,"",F28/G28) -> 0.86223071 | W28: =IF(J28=0,"",(F28-G28)/J28) -> -0.10219571 | X28: =IF(E28=0,"",(I28/E28)*Days) -> 134.4439 | Y28: =IF(J28=0,"",T28/J28) -> -0.00064169088 | Z28: =IF(E28=0,"",S28/E28) -> -0.01977463 | AA28: =IF(J28=0,"",E28/J28) -> 0.72254876 | AB28: =IF(U28=0,"",M28/J28) -> 0.054237313 | AC28: =IF(J28=0,"",U28/J28) -> 0.44099125 | AD28: =IF(J28=0,"",N28/J28) -> -0.19921571 | AE28: =IF(P28=0,"",O28/P28) -> -0.59878682 | AF28: =IF(P28=0,"N/A",S28/P28) -> -0.20888275 | AG28: =IF(U28=0,"",(S28/U28)) -> -0.03240004
B29: F05 | C29: =_xlfn.XLOOKUP(B29,Sector_Grouping!$A$4:$A$18,Sector_Grouping!$C$4:$C$18,"") -> Agri-food Industry | D29: 2023 | E29: 2689346.8 | F29: 2007725.6 | G29: 2846921.2 | H29: 65419.743 | I29: =889488.554-64806.237 -> 824682.32 | J29: 3279985.1 | K29: 1845077.4 | L29: 351970.51 | M29: 81093.353 | N29: -1156839 | O29: 94114.275 | P29: 252079.48 | Q29: -165448.13 | R29: 127213.28 | S29: 454493.72 | T29: =O29+R29 -> 221327.55 | U29: =K29+L29 -> 2197047.9 | V29: =IF(G29=0,"",F29/G29) -> 0.70522697 | W29: =IF(J29=0,"",(F29-G29)/J29) -> -0.25585348 | X29: =IF(E29=0,"",(I29/E29)*Days) -> 111.92645 | Y29: =IF(J29=0,"",T29/J29) -> 0.06747822 | Z29: =IF(E29=0,"",S29/E29) -> 0.16899781 | AA29: =IF(J29=0,"",E29/J29) -> 0.81992653 | AB29: =IF(U29=0,"",M29/J29) -> 0.024723696 | AC29: =IF(J29=0,"",U29/J29) -> 0.66983473 | AD29: =IF(J29=0,"",N29/J29) -> -0.35269644 | AE29: =IF(P29=0,"",O29/P29) -> 0.37335159 | AF29: =IF(P29=0,"N/A",S29/P29) -> 1.8029779 | AG29: =IF(U29=0,"",(S29/U29)) -> 0.20686564
B30: F05 | C30: =_xlfn.XLOOKUP(B30,Sector_Grouping!$A$4:$A$18,Sector_Grouping!$C$4:$C$18,"") -> Agri-food Industry | D30: 2024 | E30: 2496634 | F30: 2915230.3 | G30: 3354155.6 | H30: 1146010 | I30: =915034.236-64806.237 -> 850228 | J30: 4094750.2 | K30: 2031487.4 | L30: 120767.32 | M30: 619827.23 | N30: -1322287.2 | O30: 71776.714 | P30: 190706.82 | Q30: -111266.12 | R30: 93699.616 | S30: 476343.43 | T30: =O30+R30 -> 165476.33 | U30: =K30+L30 -> 2152254.7 | V30: =IF(G30=0,"",F30/G30) -> 0.86913986 | W30: =IF(J30=0,"",(F30-G30)/J30) -> -0.1071922 | X30: =IF(E30=0,"",(I30/E30)*Days) -> 124.30065 | Y30: =IF(J30=0,"",T30/J30) -> 0.040411826 | Z30: =IF(E30=0,"",S30/E30) -> 0.19079426 | AA30: =IF(J30=0,"",E30/J30) -> 0.60971582 | AB30: =IF(U30=0,"",M30/J30) -> 0.1513712 | AC30: =IF(J30=0,"",U30/J30) -> 0.5256132 | AD30: =IF(J30=0,"",N30/J30) -> -0.32292255 | AE30: =IF(P30=0,"",O30/P30) -> 0.37637205 | AF30: =IF(P30=0,"N/A",S30/P30) -> 2.4977788 | AG30: =IF(U30=0,"",(S30/U30)) -> 0.22132298
B31: F06 | C31: =_xlfn.XLOOKUP(B31,Sector_Grouping!$A$4:$A$18,Sector_Grouping!$C$4:$C$18,"") -> Manufacturing Industry | D31: 2021 | E31: 653881.62 | F31: 1471913 | G31: 18942.424 | H31: 862025.44 | I31: 303136.56 | J31: 4259632 | K31: 0 | L31: 1 | M31: 4240689.5 | N31: 0 | O31: -140626.53 | P31: 31516.061 | Q31: -109310.47 | R31: 59769.488 | S31: -49540.985 | T31: =O31+R31 -> -80857.046 | U31: =K31+L31 -> 1 | V31: =IF(G31=0,"",F31/G31) -> 77.704573 | W31: =IF(J31=0,"",(F31-G31)/J31) -> 0.34110237 | X31: =IF(E31=0,"",(I31/E31)*Days) -> 169.21235 | Y31: =IF(J31=0,"",T31/J31) -> -0.018982167 | Z31: =IF(E31=0,"",S31/E31) -> -0.075764456 | AA31: =IF(J31=0,"",E31/J31) -> 0.1535066 | AB31: =IF(U31=0,"",M31/J31) -> 0.99555304 | AC31: =IF(J31=0,"",U31/J31) -> 2.3476207e-07 | AD31: =IF(J31=0,"",N31/J31) -> 0 | AE31: =IF(P31=0,"",O31/P31) -> -4.4620593 | AF31: =IF(P31=0,"N/A",S31/P31) -> -1.5719282 | AG31: =IF(U31=0,"",(S31/U31)) -> -49540.985
B32: F06 | C32: =_xlfn.XLOOKUP(B32,Sector_Grouping!$A$4:$A$18,Sector_Grouping!$C$4:$C$18,"") -> Manufacturing Industry | D32: 2022 | E32: 3828155.2 | F32: 1513623.8 | G32: 666679.04 | H32: 225124.36 | I32: 409098.06 | J32: 4943848.9 | K32: 44058.533 | L32: 0 | M32: 4277169.8 | N32: -109310.47 | O32: 100398.29 | P32: 62989.694 | Q32: 36480.309 | R32: 110027.93 | S32: 30162.207 | T32: =O32+R32 -> 210426.22 | U32: =K32+L32 -> 44058.533 | V32: =IF(G32=0,"",F32/G32) -> 2.2703935 | W32: =IF(J32=0,"",(F32-G32)/J32) -> 0.17131282 | X32: =IF(E32=0,"",(I32/E32)*Days) -> 39.00594 | Y32: =IF(J32=0,"",T32/J32) -> 0.042563239 | Z32: =IF(E32=0,"",S32/E32) -> 0.0078790449 | AA32: =IF(J32=0,"",E32/J32) -> 0.77432691 | AB32: =IF(U32=0,"",M32/J32) -> 0.86514979 | AC32: =IF(J32=0,"",U32/J32) -> 0.008911788 | AD32: =IF(J32=0,"",N32/J32) -> -0.022110399 | AE32: =IF(P32=0,"",O32/P32) -> 1.5938843 | AF32: =IF(P32=0,"N/A",S32/P32) -> 0.47884352 | AG32: =IF(U32=0,"",(S32/U32)) -> 0.68459399
B33: F06 | C33: =_xlfn.XLOOKUP(B33,Sector_Grouping!$A$4:$A$18,Sector_Grouping!$C$4:$C$18,"") -> Manufacturing Industry | D33: 2023 | E33: 973049.91 | F33: 4234442.6 | G33: 538000.96 | H33: 3194740.6 | I33: 411634.91 | J33: 7665884.9 | K33: 8536.421 | L33: 850235.54 | M33: 6277648.4 | N33: -72830.164 | O33: -493308.15 | P33: 11928.244 | Q33: -499521.45 | R33: 230822.75 | S33: -60919.471 | T33: =O33+R33 -> -262485.4 | U33: =K33+L33 -> 858771.96 | V33: =IF(G33=0,"",F33/G33) -> 7.8706972 | W33: =IF(J33=0,"",(F33-G33)/J33) -> 0.48219374 | X33: =IF(E33=0,"",(I33/E33)*Days) -> 154.40805 | Y33: =IF(J33=0,"",T33/J33) -> -0.034240718 | Z33: =IF(E33=0,"",S33/E33) -> -0.062606728 | AA33: =IF(J33=0,"",E33/J33) -> 0.1269325 | AB33: =IF(U33=0,"",M33/J33) -> 0.81890721 | AC33: =IF(J33=0,"",U33/J33) -> 0.11202516 | AD33: =IF(J33=0,"",N33/J33) -> -0.0095005554 | AE33: =IF(P33=0,"",O33/P33) -> -41.35631 | AF33: =IF(P33=0,"N/A",S33/P33) -> -5.1071617 | AG33: =IF(U33=0,"",(S33/U33)) -> -0.070937891
B34: F06 | C34: =_xlfn.XLOOKUP(B34,Sector_Grouping!$A$4:$A$18,Sector_Grouping!$C$4:$C$18,"") -> Manufacturing Industry | D34: 2024 | E34: 1829785.1 | F34: 3398206.5 | G34: 476857.94 | H34: 231056.95 | I34: 1375632.2 | J34: 6909282.9 | K34: 9714.373 | L34: 840521.16 | M34: 5586143.8 | N34: -572351.61 | O34: -700708.53 | P34: 18378.109 | Q34: -691504.63 | R34: 242114.09 | S34: -2625970.9 | T34: =O34+R34 -> -458594.44 | U34: =K34+L34 -> 850235.54 | V34: =IF(G34=0,"",F34/G34) -> 7.1262451 | W34: =IF(J34=0,"",(F34-G34)/J34) -> 0.42281503 | X34: =IF(E34=0,"",(I34/E34)*Days) -> 274.40696 | Y34: =IF(J34=0,"",T34/J34) -> -0.066373668 | Z34: =IF(E34=0,"",S34/E34) -> -1.4351253 | AA34: =IF(J34=0,"",E34/J34) -> 0.26482996 | AB34: =IF(U34=0,"",M34/J34) -> 0.80849834 | AC34: =IF(J34=0,"",U34/J34) -> 0.12305699 | AD34: =IF(J34=0,"",N34/J34) -> -0.082838063 | AE34: =IF(P34=0,"",O34/P34) -> -38.127347 | AF34: =IF(P34=0,"N/A",S34/P34) -> -142.8858 | AG34: =IF(U34=0,"",(S34/U34)) -> -3.0885216
B35: F07 | C35: =_xlfn.XLOOKUP(B35,Sector_Grouping!$A$4:$A$18,Sector_Grouping!$C$4:$C$18,"") -> Services and Commerce | D35: 2020 | E35: 6512106 | F35: 7983504.5 | G35: 13086672 | H35: 59314.082 | I35: 3550877.5 | J35: 13815880 | K35: 9275637.9 | L35: 543407.42 | M35: 185800.29 | N35: -117126.17 | O35: -492580.28 | P35: 791983.56 | Q35: -1306847 | R35: 401209.99 | S35: 621357.44 | T35: =O35+R35 -> -91370.291 | U35: =K35+L35 -> 9819045.3 | V35: =IF(G35=0,"",F35/G35) -> 0.61004848 | W35: =IF(J35=0,"",(F35-G35)/J35) -> -0.36936972 | X35: =IF(E35=0,"",(I35/E35)*Days) -> 199.02475 | Y35: =IF(J35=0,"",T35/J35) -> -0.0066134254 | Z35: =IF(E35=0,"",S35/E35) -> 0.095415743 | AA35: =IF(J35=0,"",E35/J35) -> 0.47134935 | AB35: =IF(U35=0,"",M35/J35) -> 0.013448314 | AC35: =IF(J35=0,"",U35/J35) -> 0.7107072 | AD35: =IF(J35=0,"",N35/J35) -> -0.0084776484 | AE35: =IF(P35=0,"",O35/P35) -> -0.62195771 | AF35: =IF(P35=0,"N/A",S35/P35) -> 0.7845585 | AG35: =IF(U35=0,"",(S35/U35)) -> 0.06328084
B36: F07 | C36: =_xlfn.XLOOKUP(B36,Sector_Grouping!$A$4:$A$18,Sector_Grouping!$C$4:$C$18,"") -> Services and Commerce | D36: 2021 | E36: 10200456 | F36: 7232748.6 | G36: 8810607.1 | H36: 273376.45 | I36: 3375146 | J36: 10939341 | K36: 3721118 | L36: 2138052.1 | M36: -9317.822 | N36: -3563013.2 | O36: 173720.81 | P36: 945885.85 | Q36: 212907.47 | R36: 229002.91 | S36: 3335610.7 | T36: =O36+R36 -> 402723.72 | U36: =K36+L36 -> 5859170.2 | V36: =IF(G36=0,"",F36/G36) -> 0.82091376 | W36: =IF(J36=0,"",(F36-G36)/J36) -> -0.14423706 | X36: =IF(E36=0,"",(I36/E36)*Days) -> 120.77188 | Y36: =IF(J36=0,"",T36/J36) -> 0.036814256 | Z36: =IF(E36=0,"",S36/E36) -> 0.32700603 | AA36: =IF(J36=0,"",E36/J36) -> 0.93245616 | AB36: =IF(U36=0,"",M36/J36) -> -0.00085177175 | AC36: =IF(J36=0,"",U36/J36) -> 0.53560538 | AD36: =IF(J36=0,"",N36/J36) -> -0.32570638 | AE36: =IF(P36=0,"",O36/P36) -> 0.18365938 | AF36: =IF(P36=0,"N/A",S36/P36) -> 3.526441 | AG36: =IF(U36=0,"",(S36/U36)) -> 0.56929746
B37: F07 | C37: =_xlfn.XLOOKUP(B37,Sector_Grouping!$A$4:$A$18,Sector_Grouping!$C$4:$C$18,"") -> Services and Commerce | D37: 2022 | E37: 14456398 | F37: 10974618 | G37: 12313830 | H37: 748235.32 | I37: 5809577.2 | J37: 14627136 | K37: 9073588.9 | L37: 1703299.7 | M37: 196513.25 | N37: -3350105.8 | O37: 1330794.9 | P37: 1015349.1 | Q37: 205831.07 | R37: 191592.26 | S37: -4205927.5 | T37: =O37+R37 -> 1522387.1 | U37: =K37+L37 -> 10776889 | V37: =IF(G37=0,"",F37/G37) -> 0.89124326 | W37: =IF(J37=0,"",(F37-G37)/J37) -> -0.091556675 | X37: =IF(E37=0,"",(I37/E37)*Days) -> 146.68216 | Y37: =IF(J37=0,"",T37/J37) -> 0.10407964 | Z37: =IF(E37=0,"",S37/E37) -> -0.29093883 | AA37: =IF(J37=0,"",E37/J37) -> 0.98832731 | AB37: =IF(U37=0,"",M37/J37) -> 0.013434841 | AC37: =IF(J37=0,"",U37/J37) -> 0.73677365 | AD37: =IF(J37=0,"",N37/J37) -> -0.22903361 | AE37: =IF(P37=0,"",O37/P37) -> 1.3106772 | AF37: =IF(P37=0,"N/A",S37/P37) -> -4.1423463 | AG37: =IF(U37=0,"",(S37/U37)) -> -0.3902729
B38: F07 | C38: =_xlfn.XLOOKUP(B38,Sector_Grouping!$A$4:$A$18,Sector_Grouping!$C$4:$C$18,"") -> Services and Commerce | D38: 2023 | E38: 4007575.2 | F38: 7497180.5 | G38: 10396705 | H38: 1275613 | I38: 2456748.8 | J38: 11913920 | K38: 6392783.9 | L38: 1115538.8 | M38: 401676.69 | N38: -3144274.7 | O38: -620742.45 | P38: 992969.42 | Q38: -1909236.6 | R38: 169590.4 | S38: 1742891.6 | T38: =O38+R38 -> -451152.05 | U38: =K38+L38 -> 7508322.7 | V38: =IF(G38=0,"",F38/G38) -> 0.72111124 | W38: =IF(J38=0,"",(F38-G38)/J38) -> -0.2433728 | X38: =IF(E38=0,"",(I38/E38)*Days) -> 223.75458 | Y38: =IF(J38=0,"",T38/J38) -> -0.037867641 | Z38: =IF(E38=0,"",S38/E38) -> 0.43489929 | AA38: =IF(J38=0,"",E38/J38) -> 0.33637755 | AB38: =IF(U38=0,"",M38/J38) -> 0.033714906 | AC38: =IF(J38=0,"",U38/J38) -> 0.6302143 | AD38: =IF(J38=0,"",N38/J38) -> -0.26391605 | AE38: =IF(P38=0,"",O38/P38) -> -0.62513753 | AF38: =IF(P38=0,"N/A",S38/P38) -> 1.7552319 | AG38: =IF(U38=0,"",(S38/U38)) -> 0.23212796
B39: F07 | C39: =_xlfn.XLOOKUP(B39,Sector_Grouping!$A$4:$A$18,Sector_Grouping!$C$4:$C$18,"") -> Services and Commerce | D39: 2024 | E39: 9761652.9 | F39: 7098220.7 | G39: 8132092 | H39: 425074.43 | I39: 3271385.1 | J39: 11516166 | K39: 3942035.7 | L39: 3830000 | M39: -445925.86 | N39: -5050580.7 | O39: 403197.16 | P39: 1390658.1 | Q39: -850533.08 | R39: 43793.962 | S39: -1072401.2 | T39: =O39+R39 -> 446991.12 | U39: =K39+L39 -> 7772035.7 | V39: =IF(G39=0,"",F39/G39) -> 0.87286528 | W39: =IF(J39=0,"",(F39-G39)/J39) -> -0.089775647 | X39: =IF(E39=0,"",(I39/E39)*Days) -> 122.32104 | Y39: =IF(J39=0,"",T39/J39) -> 0.03881423 | Z39: =IF(E39=0,"",S39/E39) -> -0.10985856 | AA39: =IF(J39=0,"",E39/J39) -> 0.8476478 | AB39: =IF(U39=0,"",M39/J39) -> -0.038721729 | AC39: =IF(J39=0,"",U39/J39) -> 0.67488048 | AD39: =IF(J39=0,"",N39/J39) -> -0.43856442 | AE39: =IF(P39=0,"",O39/P39) -> 0.28993263 | AF39: =IF(P39=0,"N/A",S39/P39) -> -0.77114654 | AG39: =IF(U39=0,"",(S39/U39)) -> -0.13798202
B40: F08 | C40: =_xlfn.XLOOKUP(B40,Sector_Grouping!$A$4:$A$18,Sector_Grouping!$C$4:$C$18,"") -> Agri-food Industry | D40: 2020 | E40: 3329314 | F40: 2624021 | G40: 5855251 | H40: 66932 | I40: 1972494 | J40: 3390346 | K40: 2635442 | L40: 866554 | M40: -3331459 | N40: -3458556 | O40: -90813 | P40: 294432 | Q40: -388904 | R40: 133796 | S40: -280598 | T40: =O40+R40 -> 42983 | U40: =K40+L40 -> 3501996 | V40: =IF(G40=0,"",F40/G40) -> 0.44814834 | W40: =IF(J40=0,"",(F40-G40)/J40) -> -0.95306792 | X40: =IF(E40=0,"",(I40/E40)*Days) -> 216.24885 | Y40: =IF(J40=0,"",T40/J40) -> 0.012678057 | Z40: =IF(E40=0,"",S40/E40) -> -0.084281026 | AA40: =IF(J40=0,"",E40/J40) -> 0.9819983 | AB40: =IF(U40=0,"",M40/J40) -> -0.98263098 | AC40: =IF(J40=0,"",U40/J40) -> 1.0329317 | AD40: =IF(J40=0,"",N40/J40) -> -1.0201189 | AE40: =IF(P40=0,"",O40/P40) -> -0.30843455 | AF40: =IF(P40=0,"N/A",S40/P40) -> -0.95301462 | AG40: =IF(U40=0,"",(S40/U40)) -> -0.080125163
B41: F08 | C41: =_xlfn.XLOOKUP(B41,Sector_Grouping!$A$4:$A$18,Sector_Grouping!$C$4:$C$18,"") -> Agri-food Industry | D41: 2021 | E41: 4557050 | F41: 2388768 | G41: 5249574 | H41: 45150 | I41: 1240386 | J41: 3307648 | K41: 2536040 | L41: 1379285 | M41: -3321611 | N41: -3847459 | O41: 316250 | P41: 307823 | Q41: 9849 | R41: 151262 | S41: -131293 | T41: =O41+R41 -> 467512 | U41: =K41+L41 -> 3915325 | V41: =IF(G41=0,"",F41/G41) -> 0.45504035 | W41: =IF(J41=0,"",(F41-G41)/J41) -> -0.86490642 | X41: =IF(E41=0,"",(I41/E41)*Days) -> 99.349555 | Y41: =IF(J41=0,"",T41/J41) -> 0.14134273 | Z41: =IF(E41=0,"",S41/E41) -> -0.028810963 | AA41: =IF(J41=0,"",E41/J41) -> 1.3777312 | AB41: =IF(U41=0,"",M41/J41) -> -1.0042214 | AC41: =IF(J41=0,"",U41/J41) -> 1.1837188 | AD41: =IF(J41=0,"",N41/J41) -> -1.1632009 | AE41: =IF(P41=0,"",O41/P41) -> 1.0273761 | AF41: =IF(P41=0,"N/A",S41/P41) -> -0.42652109 | AG41: =IF(U41=0,"",(S41/U41)) -> -0.033533104
...

Sheet Formula_Dictionary
A1: Formula Dictionary
A3: Pillar | B3: Indicator | C3: Formula | D3: Economic Interpretation
A4: Liquidity | B4: Current Ratio | C4: Current Assets / Current Liabilities | D4: Shows the SME’s ability to cover its short-term obligations using its current assets.
A5: Liquidity | B5: Working Capital / Total Assets | C5: (Current Assets - Current liabilities ) / Total Assets | D5: Shows the SME’s ability to maintain short-term financial stability.
A6: Liquidity | B6: Receivables Days | C6: (Accounts receivables / Sales ) * 365 | D6: Shows how quickly the SME can recover cash from customers and avoid liquidity stress.
A7: Cash Generation | B7: EBITDA / Total Assets | C7: EBITDA / Total Assets | D7: Shows the SME’s capacity to generate operating earnings from its asset base.
A8: Cash Generation | B8: CFO / Revenue | C8: CFO / Revenue | D8: Shows the SME’s ability to transform sales into cash, strengthening resilience.
A9: Cash Generation | B9: Asset Turnover | C9: Revenue/Total Assets | D9: Shows how efficiently the SME uses its assets to support activity and continuity.
A10: Capital Structure | B10: Equity Ratio | C10: Equity / Total Assets | D10: Shows the SME’s level of financial autonomy and reliance on its own capital.
A11: Capital Structure | B11: Financial Debt / Total Assets | C11: Total Financial Debt / Total Assets | D11: Shows the SME’s overall reliance on financial debt to finance its assets.
A12: Capital Structure | B12: Retained Earnings / Total Assets | C12: Retained Earnings / Total Assets | D12: Shows the SME’s ability to finance itself using accumulated profits.
A13: Debt Sustainability | B13: Interest Coverage Ratio (ICR) | C13: EBIT / Interest Expense | D13: Shows the SME’s ability to pay interest from its operating earnings.
A14: Debt Sustainability | B14: CFO / Interest Coverage | C14: CFO / Interest Expense | D14: Shows the SME’s ability to cover interest payments using operating cash flow.
A15: Debt Sustainability | B15: CFO / Financial Debt | C15: CFO / Total Financial Debt | D15: Shows the SME’s ability to repay financial debt using operating cash flow.

Sheet Sector_Grouping
A1: Sector_Grouping_Table
A3: Firm | B3: Original_Sector | C3: Grouped_Sector
A4: F01 | B4: Restauration rapide | C4: Services and Commerce
A5: F02 | B5: La transformation du poisson | C5: Agri-food Industry
A6: F03 | B6: Emballage alimentaire | C6: Manufacturing Industry
A7: F04 | B7: Emballage en plastique | C7: Manufacturing Industry
A8: F05 | B8: Agroalimentaire | C8: Agri-food Industry
A9: F06 | B9: Découpe Papier/carton | C9: Manufacturing Industry
A10: F07 | B10: Commerce et distribution papier | C10: Services and Commerce
A11: F08 | B11: Secteur de l’industrie agroalimentaire | C11: Agri-food Industry
A12: F09 | B12: Industrie 4.0 | C12: Manufacturing Industry
A13: F10 | B13: Industrie manufacturière | C13: Manufacturing Industry
A14: F11 | B14: Marché du fibrociment | C14: Manufacturing Industry
... A18: F15 | B18: Pharmaceutique | C18: Manufacturing Industry
A28: Reference category for regression: Industrial / Manufacturing / Materials

Sheet FRI Results
A1: Final FRI Results by Firm-Year
A3: Firm | B3: Year | C3: P1 Liq. | D3: P2 Cash | E3: P3 Cap. | F3: P4 Debt | G3: FRI Score | H3: Category | I3: FRI Change | J3: Trend
A4: F01 | B4: 2020 | C4: 60.09 | D4: 69.69 | E4: 83.26 | F4: 44.89 | G4: 64.48 | H4: High Resilience | I4: N/A | J4: N/A
A5: F01 | B5: 2021 | C5: 63.74 | D5: 75.35 | E5: 82.06 | F5: 58.08 | G5: 69.81 | H5: High Resilience | I5: 5.33 | J5: Improved
A6: F01 | B6: 2022 | C6: 65.63 | D6: 94.11 | E6: 83.42 | F6: 74.96 | G6: 79.53 | H6: High Resilience | I6: 9.72 | J6: Improved
A7: F01 | B7: 2023 | C7: 65.98 | D7: 87.72 | E7: 90.24 | F7: 92.67 | G7: 84.15 | H7: High Resilience | I7: 4.62 | J7: Improved
A8: F01 | B8: 2024 | C8: 62.87 | D8: 93.46 | E8: 91.95 | F8: 100 | G8: 87.07 | H8: High Resilience | I8: 2.92 | J8: Improved
A9: F02 | B9: 2020 | C9: 42.24 | D9: 41.02 | E9: 71.39 | F9: 40.92 | G9: 48.89 | H9: Medium Resilience | I9: N/A | J9: N/A | N9: Chart : Yearly FRI Evolution Across Firms
A10: F02 | B10: 2021 | C10: 53.43 | D10: 71.06 | E10: 70.06 | F10: 72.08 | G10: 66.66 | H10: Medium Resilience | I10: 17.77 | J10: Improved
A11: F02 | B11: 2022 | C11: 49.32 | D11: 42.13 | E11: 77.39 | F11: 29.73 | G11: 49.64 | H11: Medium Resilience | I11: -17.02 | J11: Deteriorated
A12: F02 | B12: 2023 | C12: 53.19 | D12: 81.51 | E12: 68.43 | F12: 57.18 | G12: 65.08 | H12: Medium Resilience | I12: 15.44 | J12: Improved
A13: F02 | B13: 2024 | C13: 53.62 | D13: 99.46 | E13: 74.4 | F13: 86.23 | G13: 78.43 | H13: Medium Resilience | I13: 13.35 | J13: Improved
A14: F03 | B14: 2019 | C14: 43.47 | D14: 41.85 | E14: 42.64 | F14: 36.55 | G14: 41.13 | H14: Low Resilience | I14: N/A | J14: N/A
A15: F03 | B15: 2020 | C15: 32.34 | D15: 62.54 | E15: 21.05 | F15: 53.01 | G15: 42.24 | H15: Low Resilience | I15: 1.11 | J15: Improved
A16: F03 | B16: 2021 | C16: 49.97 | D16: 31.53 | E16: 35.9 | F16: 17.28 | G16: 33.67 | H16: Low Resilience | I16: -8.57 | J16: Deteriorated
A17: F03 | B17: 2022 | C17: 25.69 | D17: 62.69 | E17: 15.79 | F17: 63.24 | G17: 41.85 | H17: Low Resilience | I17: 8.18 | J17: Improved
A18: F03 | B18: 2023 | C18: 29.62 | D18: 58.49 | E18: 23.05 | F18: 74.09 | G18: 46.31 | H18: Low Resilience | I18: 4.46 | J18: Improved
A19: F04 | B19: 2020 | C19: 65.33 | D19: 44.6 | E19: 76.18 | F19: 44.02 | G19: 57.53 | H19: Low Resilience | I19: N/A | J19: N/A
A20: F04 | B20: 2021 | C20: 50.72 | D20: 53.08 | E20: 70.73 | F20: 61.74 | G20: 59.07 | H20: Low Resilience | I20: 1.54 | J20: Improved
A21: F04 | B21: 2022 | C21: 46.05 | D21: 12.31 | E21: 57.21 | F21: 27.11 | G21: 35.67 | H21: Low Resilience | I21: -23.4 | J21: Deteriorated
A22: F04 | B22: 2023 | C22: 47.44 | D22: 18.16 | E22: 69.55 | F22: 47.69 | G22: 45.71 | H22: Low Resilience | I22: 10.04 | J22: Improved
A23: F04 | B23: 2024 | C23: 55.56 | D23: 52.91 | E23: 67.82 | F23: 59.45 | G23: 58.94 | H23: Low Resilience | I23: 13.23 | J23: Improved
A24: F05 | B24: 2020 | C24: 60.31 | D24: 71.09 | E24: 62 | F24: 66.01 | G24: 64.85 | H24: High Resilience | I24: N/A | J24: N/A
A25: F05 | B25: 2021 | C25: 60.76 | D25: 65.38 | E25: 74.98 | F25: 53.17 | G25: 63.57 | H25: High Resilience | I25: -1.28 | J25: Deteriorated
A26: F05 | B26: 2022 | C26: 48.09 | D26: 62.61 | E26: 70.7 | F26: 57.06 | G26: 59.61 | H26: High Resilience | I26: -3.96 | J26: Deteriorated
A27: F05 | B27: 2023 | C27: 42.71 | D27: 77.46 | E27: 59.38 | F27: 72.24 | G27: 62.95 | H27: High Resilience | I27: 3.34 | J27: Improved
A28: F05 | B28: 2024 | C28: 49.38 | D28: 68.48 | E28: 67.55 | F28: 74.87 | G28: 65.07 | H28: High Resilience | I28: 2.12 | J28: Improved
A29: F06 | B29: 2021 | C29: 94.66 | D29: 41.89 | E29: 100 | F29: 18.98 | G29: 63.88 | H29: High Resilience | I29: N/A | J29: N/A
A30: F06 | B30: 2022 | C30: 97.42 | D30: 69.67 | E30: 99.52 | F30: 80.22 | G30: 86.71 | H30: High Resilience | I30: 22.83 | J30: Improved | T30: Source: Author’s analysis using Python
A31: F06 | B31: 2023 | C31: 99.94 | D31: 39.65 | E31: 99.79 | F31: 26.26 | G31: 66.41 | H31: High Resilience | I31: -20.3 | J31: Deteriorated
A32: F06 | B32: 2024 | C32: 83.64 | D32: 9.62 | E32: 98.19 | F32: 0 | G32: 47.86 | H32: High Resilience | I32: -18.55 | J32: Deteriorated
A33: F07 | B33: 2020 | C33: 25.5 | D33: 56.82 | E33: 65.33 | F33: 62.63 | G33: 52.57 | H33: Medium Resilience | I33: N/A | J33: N/A
A34: F07 | B34: 2021 | C34: 47.63 | D34: 80.99 | E34: 63.65 | F34: 86.31 | G34: 69.64 | H34: Medium Resilience | I34: 17.07 | J34: Improved
A35: F07 | B35: 2022 | C35: 47.41 | D35: 76.46 | E35: 59.69 | F35: 40.45 | G35: 56 | H35: Medium Resilience | I35: -13.64 | J35: Deteriorated
A36: F07 | B36: 2023 | C36: 39.74 | D36: 59.76 | E36: 62.79 | F36: 70.02 | G36: 58.08 | H36: Medium Resilience | I36: 2.08 | J36: Improved
A37: F07 | B37: 2024 | C37: 51.31 | D37: 68.86 | E37: 68.87 | F37: 78.98 | G37: 67 | H37: Medium Resilience | I37: 8.92 | J37: Improved
A38: F08 | B38: 2020 | C38: 0 | D38: 70.61 | E38: 9.92 | F38: 54.23 | G38: 33.69 | H38: Low Resilience | I38: N/A | J38: N/A
A39: F08 | B39: 2021 | C39: 18.54 | D39: 97.52 | E39: 2.78 | F39: 60.72 | G39: 44.89 | H39: Low Resilience | I39: 11.2 | J39: Improved
A40: F08 | B40: 2022 | C40: 36.27 | D40: 99.71 | E40: 6.15 | F40: 66.53 | G40: 52.17 | H40: Low Resilience | I40: 7.28 | J40: Improved
A41: F08 | B41: 2023 | C41: 31.95 | D41: 100 | E41: 11.41 | F41: 65.06 | G41: 52.1 | H41: Low Resilience | I41: -0.07 | J41: Deteriorated
...

Sheet FRI by Firm
A1: FRI Per Firm
A3: Firm | B3: N | C3: Mean FRI | D3: Median FRI | E3: Std Dev | F3: Min FRI | G3: Max FRI | H3: Resilience Category
A4: F01 | B4: 5 | C4: 77.01 | D4: 79.53 | E4: 9.58 | F4: 64.48 | G4: 87.07 | H4: High Resilience
A5: F02 | B5: 5 | C5: 61.74 | D5: 65.08 | E5: 12.5 | F5: 48.89 | G5: 78.43 | H5: Medium Resilience
A6: F03 | B6: 5 | C6: 41.04 | D6: 41.85 | E6: 4.59 | F6: 33.67 | G6: 46.31 | H6: Low Resilience
A7: F04 | B7: 5 | C7: 51.38 | D7: 57.53 | E7: 10.41 | F7: 35.67 | G7: 59.07 | H7: Low Resilience
A8: F05 | B8: 5 | C8: 63.21 | D8: 63.57 | E8: 2.2 | F8: 59.61 | G8: 65.07 | H8: High Resilience
A9: F06 | B9: 4 | C9: 66.22 | D9: 65.14 | E9: 15.94 | F9: 47.86 | G9: 86.71 | H9: High Resilience
A10: F07 | B10: 5 | C10: 60.66 | D10: 58.08 | E10: 7.33 | F10: 52.57 | G10: 69.64 | H10: Medium Resilience
A11: F08 | B11: 5 | C11: 49.3 | D11: 52.1 | E11: 11.01 | F11: 33.69 | G11: 63.65 | H11: Low Resilience
A12: F09 | B12: 5 | C12: 75.22 | D12: 76.94 | E12: 8.22 | F12: 61.51 | G12: 83.75 | H12: High Resilience
A13: F10 | B13: 5 | C13: 50.29 | D13: 47.94 | E13: 7.4 | F13: 40.65 | G13: 58.68 | H13: Low Resilience
A14: F11 | B14: 5 | C14: 35.5 | D14: 36.71 | E14: 11.14 | F14: 18.12 | G14: 47.23 | H14: Low Resilience
A15: F12 | B15: 5 | C15: 58.78 | D15: 58.03 | E15: 13.59 | F15: 40.08 | G15: 71.88 | H15: Medium Resilience
... A18: F15 | B18: 5 | C18: 54.8 | D18: 55.66 | E18: 5.11 | F18: 47.17 | G18: 60.14 | H18: Medium Resilience

Sheet Pillar_CorrelationAnalysis
A1: Within-Pillar Correlation Matrices
A2: Red>0.85 (redundant) | Yellow 0.70-0.85 | Green<0.30 (weak signal)
A3: P1 Liquidity | F3: Within the Liquidity pillar, Current Ratio and WC/Total Assets are moderately correlated (ρ = 0.823), indicating that both variables reflect short-term financial strength. However, the correlation remains below the 0.85 redundancy threshold, suggesting that each indicator still provides additional information. Receivables Days shows weaker and negative correlations with the other liquidity measures, meaning that it captures a different aspect of liquidity related to collection efficiency rather than available short-term resources. Overall, the indicators are sufficiently related without being redundant, which supports their aggregation through PCA into a single Liquidity score for the resilience index.
B4: current_ratio | C4: wc_total_assets | D4: receivables_days
A5: current_ratio | B5: 1 | C5: 0.823 | D5: -0.58
A6: wc_total_assets | B6: 0.823 | C6: 1 | D6: -0.494
A7: receivables_days | B7: -0.58 | C7: -0.494 | D7: 1
A10: P2 Cash Generation | F10: Within the Cash Generation pillar, correlations between the indicators remain relatively weak (ranging from 0.283 to 0.404), suggesting limited overlap between the measures. EBITDA/Total Assets reflects operating profitability relative to the asset base, CFO/Revenue captures the conversion of revenue into actual cash flow, and Asset Turnover measures how efficiently assets generate sales. Since each indicator captures a different dimension of cash generation capacity, retaining all three variables adds complementary information. This supports their aggregation through PCA into a single Cash Generation score for the resilience index.
B11: ebitda_total_assets | C11: cfo_revenue | D11: asset_turnover
A12: ebitda_total_assets | B12: 1 | C12: 0.283 | D12: 0.358
A13: cfo_revenue | B13: 0.283 | C13: 1 | D13: 0.404
A14: asset_turnover | B14: 0.358 | C14: 0.404 | D14: 1
A17: P3 Capital Structure | F17: Within the Capital Structure pillar, correlations are generally higher than in the other pillars. Equity Ratio and Financial Debt/Total Assets are strongly correlated (ρ = 0.890), reflecting the inverse relationship between equity and debt financing. Equity Ratio is also closely related to Retained Earnings/Total Assets (ρ = 0.836), since retained profits contribute to equity growth over time. Although some overlap exists between the indicators, PCA helps capture their shared information without double-counting, supporting their aggregation into a single Capital Structure score.
B18: equity_ratio | C18: financial_debt_total_assets | D18: retained_earnings_total_assets
A19: equity_ratio | B19: 1 | C19: 0.89 | D19: 0.836
A20: financial_debt_total_assets | B20: 0.89 | C20: 1 | D20: 0.715
A21: retained_earnings_total_assets | B21: 0.836 | C21: 0.715 | D21: 1
A24: P4 Debt Sustainability | F24: Within the Debt Sustainability pillar, ICR shows relatively weak correlations with the other indicators (0.429 and 0.410), suggesting that it captures a distinct aspect of debt sustainability related to interest repayment capacity. In contrast, CFO/Interest Coverage and CFO/Financial Debt are more strongly correlated (ρ = 0.895), reflecting their common focus on the ability of operating cash flow to support debt obligations. Overall, the indicators remain economically complementary and can therefore be aggregated through PCA into a single Debt Sustainability score.
B25: icr | C25: cfo_interest_coverage | D25: cfo_financial_debt
A26: icr | B26: 1 | C26: 0.429 | D26: 0.41
A27: cfo_interest_coverage | B27: 0.429 | C27: 1 | D27: 0.895
A28: cfo_financial_debt | B28: 0.41 | C28: 0.895 | D28: 1

Sheet PCA_Diagnostic 
A1: PCA Diagnostics — KMO, Variance & Loadings
A2: KMO values above 0.60 and PC1 explained variance above 40% indicate acceptable PCA adequacy.
A3: PCA LOG — Overview
A4: pillar | B4: kmo | C4: kmo_interpretation | D4: pc1_var_pct | E4: pc2_var_pct | F4: pc3_var_pct | G4: eigenvalue_pc1 | H4: orientation_corr | I4: flipped | J4: n_obs
A5: P1_Liquidity | B5: 0.643 | C5: Good | D5: 75.86 | E5: 18.48 | F5: 5.66 | G5: 2.3071 | H5: 0.9951 | I5: No | J5: 74
A6: P2_Cash_Generation | B6: 0.63 | C6: Good | D6: 56.64 | E6: 24.06 | F6: 19.3 | G6: 1.7225 | H6: 0.9996 | I6: No | J6: 74
A7: P3_Capital_Structure | B7: 0.669 | C7: Good | D7: 87.65 | E7: 9.65 | F7: 2.69 | G7: 2.6656 | H7: 1 | I7: No | J7: 74
A8: P4_Debt_Sustainability | B8: 0.594 | C8: Acceptable | D8: 73.01 | E8: 23.49 | F8: 3.5 | G8: 2.2204 | H8: 0.9962 | I8: No | J8: 74
A11: PC1 LOADINGS | F11: PC1 Loadings by Pillar
A12: pillar | B12: indicator | C12: pc1_loading
A13: P1_Liquidity | B13: current_ratio | C13: 0.6177
A14: P1_Liquidity | B14: wc_total_assets | C14: 0.5968
A15: P1_Liquidity | B15: receivables_days | C15: -0.5122
A16: P2_Cash_Generation | B16: ebitda_total_assets | C16: 0.5452
A17: P2_Cash_Generation | B17: cfo_revenue | C17: 0.5737
A18: P2_Cash_Generation | B18: asset_turnover | C18: 0.6112
A19: P3_Capital_Structure | B19: equity_ratio | C19: 0.5997
A20: P3_Capital_Structure | B20: financial_debt_total_assets | C20: 0.5727
A21: P3_Capital_Structure | B21: retained_earnings_total_assets | C21: 0.5589
A22: P4_Debt_Sustainability | B22: icr | C22: 0.4461
A23: P4_Debt_Sustainability | B23: cfo_interest_coverage | C23: 0.6349
A24: P4_Debt_Sustainability | B24: cfo_financial_debt | C24: 0.6308
G33: Source: Author’s analysis using Python

Sheet FRI_Visualizations
A1: FRI Visualizations
C5: Chart 1: FRI Score Distribution | AM5: Chart 2 : FRI Heatmap Firm x Year
D24: Source: Author’s analysis using Python | AL24: Source: Author’s analysis using Python
D27: Chart 3 : Pillar Score Boxplots | AM27: Chart 4 : Yearly FRI Evolution Across Firms
D45: Source: Author’s analysis using Python | AM45: Source: Author’s analysis using Python

Sheet Descriptives
A1: Descriptive Statistics and Normality Assessment
A3: variable | B3: n | C3: mean | D3: median | E3: std | F3: skew | G3: kurtosis | H3: shapiro_W | I3: shapiro_p | J3: normal
A4: Delta_FRI | B4: 59 | C4: 0.86 | D4: 1.54 | E4: 11.93 | F4: -0.09 | G4: -0.52 | H4: 0.99 | I4: 0.8253 | J4: Yes
A5: ROA | B5: 74 | C5: -0.1 | D5: -0.07 | E5: 0.15 | F5: -1.45 | G5: 3.26 | H5: 0.9 | I5: 0 | J5: No
A6: Net_Margin | B6: 74 | C6: -0.4 | D6: -0.15 | E6: 0.64 | F6: -2.12 | G6: 5.45 | H6: 0.77 | I6: 0 | J6: No
A7: EBITDA_Margin | B7: 74 | C7: -0.07 | D7: 0.01 | E7: 0.33 | F7: -0.75 | G7: 2.64 | H7: 0.9 | I7: 0 | J7: No
A8: FRI_score | B8: 74 | C8: 58.05 | D8: 58.81 | E8: 14.68 | F8: -0.06 | G8: -0.23 | H8: 0.99 | I8: 0.5982 | J8: Yes
A10: The variables ROA, Net_Margin, and EBITDA_Margin fail the normality test (p < 0.05), meaning their distributions deviate significantly from normality. This is consistent with what is commonly observed in SME financial data, where profitability metrics tend to be skewed because of loss-making firms or outlier performers. By contrast, Delta_FRI and FRI_score both pass the Shapiro–Wilk test (p > 0.05) and therefore follow a normal distribution. Consequently, non-parametric methods were retained for the subsequent analyses.

Sheet Spearman
A1: Spearman rank correlation | J1: Spearman Correlation Matrix between ΔFRI and Profitability Indicators
A2: Fisher-z 95% CI
A3: Variable Pair | B3: n | C3: rho | D3: p_value | E3: sig | F3: CI_low | G3: CI_high
A4: Delta_FRI vs ROA | B4: 59 | C4: 0.39 | D4: 0.0002 | E4: ** | F4: 0.14 | G4: 0.58
A5: Delta_FRI vs Net_Margin | B5: 59 | C5: 0.39 | D5: 0.0001 | E5: ** | F5: 0.15 | G5: 0.59
A6: Delta_FRI vs EBITDA_Margin | B6: 59 | C6: 0.44 | D6: 0 | E6: *** | F6: 0.21 | G6: 0.62
A8: All three correlations are positive and highly significant (p < 0.001), with Spearman's ρ ranging from 0.39 to 0.44. This indicates that firms experiencing greater improvements in their Financial Resilience Index (ΔFRI) tend to exhibit stronger profitability performance across all three measures (ROA, Net Margin, and EBITDA Margin). The confidence intervals remain entirely above zero, reinforcing the robustness and reliability of these positive associations. While the correlations are moderate in magnitude, they provide initial empirical support for the relevance of improvements in financial resilience as a factor associated with enhanced firm profitability.
M13: Source: Author’s analysis using Python

Sheet Bootstrap
A1: Bootstrap robustness check | J1: Bootstrap Validation of Spearman Correlations
A2: 5,000 resamples of the Spearman ρ — 95% percentile CIs
A3: pair | B3: rho_mean | C3: CI_low | D3: CI_high | E3: excl_zero
A4: Delta_FRI vs ROA | B4: 0.38 | C4: 0.12 | D4: 0.6 | E4: Yes
A5: Delta_FRI vs Net_Margin | B5: 0.39 | C5: 0.14 | D5: 0.6 | E5: Yes
A6: Delta_FRI vs EBITDA_Margin | B6: 0.43 | C6: 0.17 | D6: 0.67 | E6: Yes
A8: The bootstrap test confirms that the Spearman correlations are stable and reliable. After 5,000 random resamples, the results barely change and all confidence intervals remain entirely above zero , meaning the relationships between Delta_FRI and the three profitability variables are robust, not driven by a few unusual observations.
M14: Source: Author’s analysis using Python
H16: The bootstrap distributions appear approximately bell-shaped and centered around the original Spearman coefficients, indicating stable and robust correlation estimates across resamples.

Sheet Wilcoxon
A1: Wilcoxon Signed-Rank Test: FRI Before vs After MPM
A3: Metric | B3: Value | E3: The Wilcoxon Signed-Rank test compares FRI scores before and after MPM's investment. Out of the 15 firms, 10 experienced an improvement in their FRI score, while 5 showed a decline. The average change was positive (+2.21 points) and the median change was +2.39 points, suggesting a general tendency toward improved financial resilience following MPM's involvement. However, the observed increase is not statistically significant (p = 0.359), meaning that the improvement cannot be distinguished from random variation at conventional significance levels. Given the limited sample size and the relatively short observation period, the evidence is insufficient to conclude that MPM's investment systematically improves financial resilience. These findings should therefore be interpreted as indicative rather than conclusive.
A4: N effective | B4: 15
A5: Improved | B5: 10
A6: Declined | B6: 5
A7: Mean difference | B7: 2.21
A8: Median difference | B8: 2.39
A9: W statistic | B9: 43
A10: p-value (two-sided) | B10: 0.3591
A11: p-value (one-sided 'greater') | B11: 0.1796
A12: Effect size r | B12: 0.24
A15: Firm-Level FRI Changes
A17: Firm_ID | B17: FRI_pre | C17: FRI_post | D17: Difference
A18: F01 | B18: 67.15 | C18: 85.61 | D18: 18.46
A19: F02 | B19: 57.78 | C19: 71.76 | D19: 13.98
A20: F03 | B20: 41.68 | C20: 44.08 | D20: 2.39
A21: F04 | B21: 58.3 | C21: 52.32 | D21: -5.97
A22: F05 | B22: 64.21 | C22: 64.01 | D22: -0.2
A23: F06 | B23: 75.3 | C23: 57.14 | D23: -18.16
A24: F07 | B24: 61.1 | C24: 62.54 | D24: 1.43
A25: F08 | B25: 39.29 | C25: 57.88 | D25: 18.58
A26: F09 | B26: 68.96 | C26: 77.21 | D26: 8.25
A27: F10 | B27: 52.09 | C27: 53.31 | D27: 1.22
A28: F11 | B28: 41.97 | C28: 30.29 | D28: -11.68
A29: F12 | B29: 71.88 | C29: 46.06 | D29: -25.82
... A32: F15 | B32: 55.51 | C32: 57.9 | D32: 2.39

Sheet Governance_Score
B1: Governance Score calculation
B3: Method : Score dimension = (sum of 4 questions / 12) × 100 | Final score = average of 4 dimensions
B5: Code | C5: Question | D5: F01 | E5: F02 | F5: F03 | G5: F04 | H5: F05 | I5: F06 | J5: F07 | K5: F08 | L5: F09 | M5: F10 | N5: F11 | O5: F12 | P5: F13 | Q5: F14 | R5: F15
D6: Score | E6: Score | F6: Score | G6: Score | H6: Score | I6: Score | J6: Score | K6: Score | L6: Score | M6: Score | N6: Score | O6: Score | P6: Score | Q6: Score | R6: Score
B7: Dimension 1 : Governance Structure and Strategic Oversight
B8: 1.1 | C8: Does the company rely on a defined body or mechanism (board, management committee or equivalent ... ) that meets on a regular basis ? 0= No identifiable body, decisions are mainly made by one person 1= Informal groups , but with no fixed meetings 2= Defined body , that meets occasionally , not in a regular manner 3= Defined body with scheduled and documented assembly | D8: 3 | E8: 3 | F8: 2 | G8: 3 | H8: 1 | I8: 2 | J8: 3 | K8: 3 | L8: 3 | M8: 3 | N8: 2 | O8: 3 | P8: 3 | Q8: 3 | R8: 3
B9: 1.2 | C9: How many specialized governance committees or equivalent mechanisms does the company have? 0=No specialized committee or equivalent mechanism 1=Informal mechanism only, without a formal committee 2=One specialized committee or equivalent mechanism 3=Two or more specialized committees or equivalent mechanisms | D9: 2 | E9: 3 | F9: 2 | G9: 2 | H9: 2 | I9: 2 | J9: 2 | K9: 2 | L9: 2 | M9: 3 | N9: 2 | O9: 2 | P9: 2 | Q9: 2 | R9: 3
